[rank: 0] Global seed set to 0
Downloading: "https://huggingface.co/torchgeo/vit_small_patch16_224_sentinel2_all_moco/resolve/main/vit_small_patch16_224_sentinel2_all_moco-67c9032d.pth" to /home/yichia3/.cache/torch/hub/checkpoints/vit_small_patch16_224_sentinel2_all_moco-67c9032d.pth
  0%|          | 0.00/86.5M [00:00<?, ?B/s]  3%|▎         | 2.52M/86.5M [00:00<00:03, 26.4MB/s]  9%|▉         | 8.09M/86.5M [00:00<00:01, 45.0MB/s] 21%|██        | 17.9M/86.5M [00:00<00:01, 71.5MB/s] 33%|███▎      | 28.4M/86.5M [00:00<00:00, 86.4MB/s] 43%|████▎     | 37.6M/86.5M [00:00<00:00, 69.0MB/s] 58%|█████▊    | 49.9M/86.5M [00:00<00:00, 60.4MB/s] 77%|███████▋  | 66.5M/86.5M [00:00<00:00, 85.7MB/s] 88%|████████▊ | 76.2M/86.5M [00:01<00:00, 77.8MB/s]100%|██████████| 86.5M/86.5M [00:01<00:00, 78.3MB/s]
Traceback (most recent call last):
  File "/projects/dali/spack/var/spack/environments/dali/.spack-env/view/lib/python3.10/site-packages/hydra/_internal/instantiate/_instantiate2.py", line 92, in _call_target
    return _target_(*args, **kwargs)
  File "/home/yichia3/agrifieldnet/torchgeo/torchgeo/trainers/segmentation.py", line 187, in __init__
    self.config_task()
  File "/home/yichia3/agrifieldnet/torchgeo/torchgeo/trainers/segmentation.py", line 111, in config_task
    state_dict["conv1.weight"] = state_dict["conv1.weight"][:,:12,:,:]
KeyError: 'conv1.weight'

The above exception was the direct cause of the following exception:

Traceback (most recent call last):
  File "/home/yichia3/agrifieldnet/torchgeo/train.py", line 193, in <module>
    main(conf)
  File "/home/yichia3/agrifieldnet/torchgeo/train.py", line 120, in main
    task: LightningModule = instantiate(conf.module)
  File "/projects/dali/spack/var/spack/environments/dali/.spack-env/view/lib/python3.10/site-packages/hydra/_internal/instantiate/_instantiate2.py", line 226, in instantiate
    return instantiate_node(
  File "/projects/dali/spack/var/spack/environments/dali/.spack-env/view/lib/python3.10/site-packages/hydra/_internal/instantiate/_instantiate2.py", line 347, in instantiate_node
    return _call_target(_target_, partial, args, kwargs, full_key)
  File "/projects/dali/spack/var/spack/environments/dali/.spack-env/view/lib/python3.10/site-packages/hydra/_internal/instantiate/_instantiate2.py", line 97, in _call_target
    raise InstantiationException(msg) from e
hydra.errors.InstantiationException: Error in call to target 'torchgeo.trainers.segmentation.SemanticSegmentationTask':
KeyError('conv1.weight')
full_key: module
[rank: 0] Global seed set to 1
Traceback (most recent call last):
  File "/projects/dali/spack/var/spack/environments/dali/.spack-env/view/lib/python3.10/site-packages/hydra/_internal/instantiate/_instantiate2.py", line 92, in _call_target
    return _target_(*args, **kwargs)
  File "/home/yichia3/agrifieldnet/torchgeo/torchgeo/trainers/segmentation.py", line 187, in __init__
    self.config_task()
  File "/home/yichia3/agrifieldnet/torchgeo/torchgeo/trainers/segmentation.py", line 111, in config_task
    state_dict["conv1.weight"] = state_dict["conv1.weight"][:,:12,:,:]
KeyError: 'conv1.weight'

The above exception was the direct cause of the following exception:

Traceback (most recent call last):
  File "/home/yichia3/agrifieldnet/torchgeo/train.py", line 193, in <module>
    main(conf)
  File "/home/yichia3/agrifieldnet/torchgeo/train.py", line 120, in main
    task: LightningModule = instantiate(conf.module)
  File "/projects/dali/spack/var/spack/environments/dali/.spack-env/view/lib/python3.10/site-packages/hydra/_internal/instantiate/_instantiate2.py", line 226, in instantiate
    return instantiate_node(
  File "/projects/dali/spack/var/spack/environments/dali/.spack-env/view/lib/python3.10/site-packages/hydra/_internal/instantiate/_instantiate2.py", line 347, in instantiate_node
    return _call_target(_target_, partial, args, kwargs, full_key)
  File "/projects/dali/spack/var/spack/environments/dali/.spack-env/view/lib/python3.10/site-packages/hydra/_internal/instantiate/_instantiate2.py", line 97, in _call_target
    raise InstantiationException(msg) from e
hydra.errors.InstantiationException: Error in call to target 'torchgeo.trainers.segmentation.SemanticSegmentationTask':
KeyError('conv1.weight')
full_key: module
[rank: 0] Global seed set to 2
Traceback (most recent call last):
  File "/projects/dali/spack/var/spack/environments/dali/.spack-env/view/lib/python3.10/site-packages/hydra/_internal/instantiate/_instantiate2.py", line 92, in _call_target
    return _target_(*args, **kwargs)
  File "/home/yichia3/agrifieldnet/torchgeo/torchgeo/trainers/segmentation.py", line 187, in __init__
    self.config_task()
  File "/home/yichia3/agrifieldnet/torchgeo/torchgeo/trainers/segmentation.py", line 111, in config_task
    state_dict["conv1.weight"] = state_dict["conv1.weight"][:,:12,:,:]
KeyError: 'conv1.weight'

The above exception was the direct cause of the following exception:

Traceback (most recent call last):
  File "/home/yichia3/agrifieldnet/torchgeo/train.py", line 193, in <module>
    main(conf)
  File "/home/yichia3/agrifieldnet/torchgeo/train.py", line 120, in main
    task: LightningModule = instantiate(conf.module)
  File "/projects/dali/spack/var/spack/environments/dali/.spack-env/view/lib/python3.10/site-packages/hydra/_internal/instantiate/_instantiate2.py", line 226, in instantiate
    return instantiate_node(
  File "/projects/dali/spack/var/spack/environments/dali/.spack-env/view/lib/python3.10/site-packages/hydra/_internal/instantiate/_instantiate2.py", line 347, in instantiate_node
    return _call_target(_target_, partial, args, kwargs, full_key)
  File "/projects/dali/spack/var/spack/environments/dali/.spack-env/view/lib/python3.10/site-packages/hydra/_internal/instantiate/_instantiate2.py", line 97, in _call_target
    raise InstantiationException(msg) from e
hydra.errors.InstantiationException: Error in call to target 'torchgeo.trainers.segmentation.SemanticSegmentationTask':
KeyError('conv1.weight')
full_key: module
[rank: 0] Global seed set to 0
Downloading: "https://huggingface.co/torchgeo/vit_small_patch16_224_sentinel2_all_dino/resolve/main/vit_small_patch16_224_sentinel2_all_dino-36bcc127.pth" to /home/yichia3/.cache/torch/hub/checkpoints/vit_small_patch16_224_sentinel2_all_dino-36bcc127.pth
  0%|          | 0.00/86.4M [00:00<?, ?B/s]  4%|▍         | 3.66M/86.4M [00:00<00:02, 37.0MB/s] 14%|█▍        | 12.1M/86.4M [00:00<00:01, 66.7MB/s] 29%|██▉       | 24.9M/86.4M [00:00<00:00, 69.0MB/s] 49%|████▉     | 42.6M/86.4M [00:00<00:00, 94.2MB/s] 60%|█████▉    | 51.6M/86.4M [00:00<00:00, 64.7MB/s] 79%|███████▊  | 68.0M/86.4M [00:00<00:00, 88.2MB/s] 91%|█████████ | 78.2M/86.4M [00:01<00:00, 75.3MB/s]100%|██████████| 86.4M/86.4M [00:01<00:00, 78.9MB/s]
Traceback (most recent call last):
  File "/projects/dali/spack/var/spack/environments/dali/.spack-env/view/lib/python3.10/site-packages/hydra/_internal/instantiate/_instantiate2.py", line 92, in _call_target
    return _target_(*args, **kwargs)
  File "/home/yichia3/agrifieldnet/torchgeo/torchgeo/trainers/segmentation.py", line 187, in __init__
    self.config_task()
  File "/home/yichia3/agrifieldnet/torchgeo/torchgeo/trainers/segmentation.py", line 111, in config_task
    state_dict["conv1.weight"] = state_dict["conv1.weight"][:,:12,:,:]
KeyError: 'conv1.weight'

The above exception was the direct cause of the following exception:

Traceback (most recent call last):
  File "/home/yichia3/agrifieldnet/torchgeo/train.py", line 193, in <module>
    main(conf)
  File "/home/yichia3/agrifieldnet/torchgeo/train.py", line 120, in main
    task: LightningModule = instantiate(conf.module)
  File "/projects/dali/spack/var/spack/environments/dali/.spack-env/view/lib/python3.10/site-packages/hydra/_internal/instantiate/_instantiate2.py", line 226, in instantiate
    return instantiate_node(
  File "/projects/dali/spack/var/spack/environments/dali/.spack-env/view/lib/python3.10/site-packages/hydra/_internal/instantiate/_instantiate2.py", line 347, in instantiate_node
    return _call_target(_target_, partial, args, kwargs, full_key)
  File "/projects/dali/spack/var/spack/environments/dali/.spack-env/view/lib/python3.10/site-packages/hydra/_internal/instantiate/_instantiate2.py", line 97, in _call_target
    raise InstantiationException(msg) from e
hydra.errors.InstantiationException: Error in call to target 'torchgeo.trainers.segmentation.SemanticSegmentationTask':
KeyError('conv1.weight')
full_key: module
[rank: 0] Global seed set to 1
Traceback (most recent call last):
  File "/projects/dali/spack/var/spack/environments/dali/.spack-env/view/lib/python3.10/site-packages/hydra/_internal/instantiate/_instantiate2.py", line 92, in _call_target
    return _target_(*args, **kwargs)
  File "/home/yichia3/agrifieldnet/torchgeo/torchgeo/trainers/segmentation.py", line 187, in __init__
    self.config_task()
  File "/home/yichia3/agrifieldnet/torchgeo/torchgeo/trainers/segmentation.py", line 111, in config_task
    state_dict["conv1.weight"] = state_dict["conv1.weight"][:,:12,:,:]
KeyError: 'conv1.weight'

The above exception was the direct cause of the following exception:

Traceback (most recent call last):
  File "/home/yichia3/agrifieldnet/torchgeo/train.py", line 193, in <module>
    main(conf)
  File "/home/yichia3/agrifieldnet/torchgeo/train.py", line 120, in main
    task: LightningModule = instantiate(conf.module)
  File "/projects/dali/spack/var/spack/environments/dali/.spack-env/view/lib/python3.10/site-packages/hydra/_internal/instantiate/_instantiate2.py", line 226, in instantiate
    return instantiate_node(
  File "/projects/dali/spack/var/spack/environments/dali/.spack-env/view/lib/python3.10/site-packages/hydra/_internal/instantiate/_instantiate2.py", line 347, in instantiate_node
    return _call_target(_target_, partial, args, kwargs, full_key)
  File "/projects/dali/spack/var/spack/environments/dali/.spack-env/view/lib/python3.10/site-packages/hydra/_internal/instantiate/_instantiate2.py", line 97, in _call_target
    raise InstantiationException(msg) from e
hydra.errors.InstantiationException: Error in call to target 'torchgeo.trainers.segmentation.SemanticSegmentationTask':
KeyError('conv1.weight')
full_key: module
[rank: 0] Global seed set to 2
Traceback (most recent call last):
  File "/projects/dali/spack/var/spack/environments/dali/.spack-env/view/lib/python3.10/site-packages/hydra/_internal/instantiate/_instantiate2.py", line 92, in _call_target
    return _target_(*args, **kwargs)
  File "/home/yichia3/agrifieldnet/torchgeo/torchgeo/trainers/segmentation.py", line 187, in __init__
    self.config_task()
  File "/home/yichia3/agrifieldnet/torchgeo/torchgeo/trainers/segmentation.py", line 111, in config_task
    state_dict["conv1.weight"] = state_dict["conv1.weight"][:,:12,:,:]
KeyError: 'conv1.weight'

The above exception was the direct cause of the following exception:

Traceback (most recent call last):
  File "/home/yichia3/agrifieldnet/torchgeo/train.py", line 193, in <module>
    main(conf)
  File "/home/yichia3/agrifieldnet/torchgeo/train.py", line 120, in main
    task: LightningModule = instantiate(conf.module)
  File "/projects/dali/spack/var/spack/environments/dali/.spack-env/view/lib/python3.10/site-packages/hydra/_internal/instantiate/_instantiate2.py", line 226, in instantiate
    return instantiate_node(
  File "/projects/dali/spack/var/spack/environments/dali/.spack-env/view/lib/python3.10/site-packages/hydra/_internal/instantiate/_instantiate2.py", line 347, in instantiate_node
    return _call_target(_target_, partial, args, kwargs, full_key)
  File "/projects/dali/spack/var/spack/environments/dali/.spack-env/view/lib/python3.10/site-packages/hydra/_internal/instantiate/_instantiate2.py", line 97, in _call_target
    raise InstantiationException(msg) from e
hydra.errors.InstantiationException: Error in call to target 'torchgeo.trainers.segmentation.SemanticSegmentationTask':
KeyError('conv1.weight')
full_key: module
[rank: 0] Global seed set to 0
Traceback (most recent call last):
  File "/projects/dali/spack/var/spack/environments/dali/.spack-env/view/lib/python3.10/site-packages/hydra/_internal/instantiate/_instantiate2.py", line 92, in _call_target
    return _target_(*args, **kwargs)
  File "/home/yichia3/agrifieldnet/torchgeo/torchgeo/trainers/segmentation.py", line 187, in __init__
    self.config_task()
  File "/home/yichia3/agrifieldnet/torchgeo/torchgeo/trainers/segmentation.py", line 111, in config_task
    state_dict["conv1.weight"] = state_dict["conv1.weight"][:,:12,:,:]
KeyError: 'conv1.weight'

The above exception was the direct cause of the following exception:

Traceback (most recent call last):
  File "/home/yichia3/agrifieldnet/torchgeo/train.py", line 193, in <module>
    main(conf)
  File "/home/yichia3/agrifieldnet/torchgeo/train.py", line 120, in main
    task: LightningModule = instantiate(conf.module)
  File "/projects/dali/spack/var/spack/environments/dali/.spack-env/view/lib/python3.10/site-packages/hydra/_internal/instantiate/_instantiate2.py", line 226, in instantiate
    return instantiate_node(
  File "/projects/dali/spack/var/spack/environments/dali/.spack-env/view/lib/python3.10/site-packages/hydra/_internal/instantiate/_instantiate2.py", line 347, in instantiate_node
    return _call_target(_target_, partial, args, kwargs, full_key)
  File "/projects/dali/spack/var/spack/environments/dali/.spack-env/view/lib/python3.10/site-packages/hydra/_internal/instantiate/_instantiate2.py", line 97, in _call_target
    raise InstantiationException(msg) from e
hydra.errors.InstantiationException: Error in call to target 'torchgeo.trainers.segmentation.SemanticSegmentationTask':
KeyError('conv1.weight')
full_key: module
[rank: 0] Global seed set to 1
Traceback (most recent call last):
  File "/projects/dali/spack/var/spack/environments/dali/.spack-env/view/lib/python3.10/site-packages/hydra/_internal/instantiate/_instantiate2.py", line 92, in _call_target
    return _target_(*args, **kwargs)
  File "/home/yichia3/agrifieldnet/torchgeo/torchgeo/trainers/segmentation.py", line 187, in __init__
    self.config_task()
  File "/home/yichia3/agrifieldnet/torchgeo/torchgeo/trainers/segmentation.py", line 111, in config_task
    state_dict["conv1.weight"] = state_dict["conv1.weight"][:,:12,:,:]
KeyError: 'conv1.weight'

The above exception was the direct cause of the following exception:

Traceback (most recent call last):
  File "/home/yichia3/agrifieldnet/torchgeo/train.py", line 193, in <module>
    main(conf)
  File "/home/yichia3/agrifieldnet/torchgeo/train.py", line 120, in main
    task: LightningModule = instantiate(conf.module)
  File "/projects/dali/spack/var/spack/environments/dali/.spack-env/view/lib/python3.10/site-packages/hydra/_internal/instantiate/_instantiate2.py", line 226, in instantiate
    return instantiate_node(
  File "/projects/dali/spack/var/spack/environments/dali/.spack-env/view/lib/python3.10/site-packages/hydra/_internal/instantiate/_instantiate2.py", line 347, in instantiate_node
    return _call_target(_target_, partial, args, kwargs, full_key)
  File "/projects/dali/spack/var/spack/environments/dali/.spack-env/view/lib/python3.10/site-packages/hydra/_internal/instantiate/_instantiate2.py", line 97, in _call_target
    raise InstantiationException(msg) from e
hydra.errors.InstantiationException: Error in call to target 'torchgeo.trainers.segmentation.SemanticSegmentationTask':
KeyError('conv1.weight')
full_key: module
[rank: 0] Global seed set to 2
Traceback (most recent call last):
  File "/projects/dali/spack/var/spack/environments/dali/.spack-env/view/lib/python3.10/site-packages/hydra/_internal/instantiate/_instantiate2.py", line 92, in _call_target
    return _target_(*args, **kwargs)
  File "/home/yichia3/agrifieldnet/torchgeo/torchgeo/trainers/segmentation.py", line 187, in __init__
    self.config_task()
  File "/home/yichia3/agrifieldnet/torchgeo/torchgeo/trainers/segmentation.py", line 111, in config_task
    state_dict["conv1.weight"] = state_dict["conv1.weight"][:,:12,:,:]
KeyError: 'conv1.weight'

The above exception was the direct cause of the following exception:

Traceback (most recent call last):
  File "/home/yichia3/agrifieldnet/torchgeo/train.py", line 193, in <module>
    main(conf)
  File "/home/yichia3/agrifieldnet/torchgeo/train.py", line 120, in main
    task: LightningModule = instantiate(conf.module)
  File "/projects/dali/spack/var/spack/environments/dali/.spack-env/view/lib/python3.10/site-packages/hydra/_internal/instantiate/_instantiate2.py", line 226, in instantiate
    return instantiate_node(
  File "/projects/dali/spack/var/spack/environments/dali/.spack-env/view/lib/python3.10/site-packages/hydra/_internal/instantiate/_instantiate2.py", line 347, in instantiate_node
    return _call_target(_target_, partial, args, kwargs, full_key)
  File "/projects/dali/spack/var/spack/environments/dali/.spack-env/view/lib/python3.10/site-packages/hydra/_internal/instantiate/_instantiate2.py", line 97, in _call_target
    raise InstantiationException(msg) from e
hydra.errors.InstantiationException: Error in call to target 'torchgeo.trainers.segmentation.SemanticSegmentationTask':
KeyError('conv1.weight')
full_key: module
[rank: 0] Global seed set to 0
Traceback (most recent call last):
  File "/projects/dali/spack/var/spack/environments/dali/.spack-env/view/lib/python3.10/site-packages/hydra/_internal/instantiate/_instantiate2.py", line 92, in _call_target
    return _target_(*args, **kwargs)
  File "/home/yichia3/agrifieldnet/torchgeo/torchgeo/trainers/segmentation.py", line 187, in __init__
    self.config_task()
  File "/home/yichia3/agrifieldnet/torchgeo/torchgeo/trainers/segmentation.py", line 111, in config_task
    state_dict["conv1.weight"] = state_dict["conv1.weight"][:,:12,:,:]
KeyError: 'conv1.weight'

The above exception was the direct cause of the following exception:

Traceback (most recent call last):
  File "/home/yichia3/agrifieldnet/torchgeo/train.py", line 193, in <module>
    main(conf)
  File "/home/yichia3/agrifieldnet/torchgeo/train.py", line 120, in main
    task: LightningModule = instantiate(conf.module)
  File "/projects/dali/spack/var/spack/environments/dali/.spack-env/view/lib/python3.10/site-packages/hydra/_internal/instantiate/_instantiate2.py", line 226, in instantiate
    return instantiate_node(
  File "/projects/dali/spack/var/spack/environments/dali/.spack-env/view/lib/python3.10/site-packages/hydra/_internal/instantiate/_instantiate2.py", line 347, in instantiate_node
    return _call_target(_target_, partial, args, kwargs, full_key)
  File "/projects/dali/spack/var/spack/environments/dali/.spack-env/view/lib/python3.10/site-packages/hydra/_internal/instantiate/_instantiate2.py", line 97, in _call_target
    raise InstantiationException(msg) from e
hydra.errors.InstantiationException: Error in call to target 'torchgeo.trainers.segmentation.SemanticSegmentationTask':
KeyError('conv1.weight')
full_key: module
[rank: 0] Global seed set to 1
Traceback (most recent call last):
  File "/projects/dali/spack/var/spack/environments/dali/.spack-env/view/lib/python3.10/site-packages/hydra/_internal/instantiate/_instantiate2.py", line 92, in _call_target
    return _target_(*args, **kwargs)
  File "/home/yichia3/agrifieldnet/torchgeo/torchgeo/trainers/segmentation.py", line 187, in __init__
    self.config_task()
  File "/home/yichia3/agrifieldnet/torchgeo/torchgeo/trainers/segmentation.py", line 111, in config_task
    state_dict["conv1.weight"] = state_dict["conv1.weight"][:,:12,:,:]
KeyError: 'conv1.weight'

The above exception was the direct cause of the following exception:

Traceback (most recent call last):
  File "/home/yichia3/agrifieldnet/torchgeo/train.py", line 193, in <module>
    main(conf)
  File "/home/yichia3/agrifieldnet/torchgeo/train.py", line 120, in main
    task: LightningModule = instantiate(conf.module)
  File "/projects/dali/spack/var/spack/environments/dali/.spack-env/view/lib/python3.10/site-packages/hydra/_internal/instantiate/_instantiate2.py", line 226, in instantiate
    return instantiate_node(
  File "/projects/dali/spack/var/spack/environments/dali/.spack-env/view/lib/python3.10/site-packages/hydra/_internal/instantiate/_instantiate2.py", line 347, in instantiate_node
    return _call_target(_target_, partial, args, kwargs, full_key)
  File "/projects/dali/spack/var/spack/environments/dali/.spack-env/view/lib/python3.10/site-packages/hydra/_internal/instantiate/_instantiate2.py", line 97, in _call_target
    raise InstantiationException(msg) from e
hydra.errors.InstantiationException: Error in call to target 'torchgeo.trainers.segmentation.SemanticSegmentationTask':
KeyError('conv1.weight')
full_key: module
[rank: 0] Global seed set to 2
Traceback (most recent call last):
  File "/projects/dali/spack/var/spack/environments/dali/.spack-env/view/lib/python3.10/site-packages/hydra/_internal/instantiate/_instantiate2.py", line 92, in _call_target
    return _target_(*args, **kwargs)
  File "/home/yichia3/agrifieldnet/torchgeo/torchgeo/trainers/segmentation.py", line 187, in __init__
    self.config_task()
  File "/home/yichia3/agrifieldnet/torchgeo/torchgeo/trainers/segmentation.py", line 111, in config_task
    state_dict["conv1.weight"] = state_dict["conv1.weight"][:,:12,:,:]
KeyError: 'conv1.weight'

The above exception was the direct cause of the following exception:

Traceback (most recent call last):
  File "/home/yichia3/agrifieldnet/torchgeo/train.py", line 193, in <module>
    main(conf)
  File "/home/yichia3/agrifieldnet/torchgeo/train.py", line 120, in main
    task: LightningModule = instantiate(conf.module)
  File "/projects/dali/spack/var/spack/environments/dali/.spack-env/view/lib/python3.10/site-packages/hydra/_internal/instantiate/_instantiate2.py", line 226, in instantiate
    return instantiate_node(
  File "/projects/dali/spack/var/spack/environments/dali/.spack-env/view/lib/python3.10/site-packages/hydra/_internal/instantiate/_instantiate2.py", line 347, in instantiate_node
    return _call_target(_target_, partial, args, kwargs, full_key)
  File "/projects/dali/spack/var/spack/environments/dali/.spack-env/view/lib/python3.10/site-packages/hydra/_internal/instantiate/_instantiate2.py", line 97, in _call_target
    raise InstantiationException(msg) from e
hydra.errors.InstantiationException: Error in call to target 'torchgeo.trainers.segmentation.SemanticSegmentationTask':
KeyError('conv1.weight')
full_key: module
[rank: 0] Global seed set to 0
Traceback (most recent call last):
  File "/projects/dali/spack/var/spack/environments/dali/.spack-env/view/lib/python3.10/site-packages/hydra/_internal/instantiate/_instantiate2.py", line 92, in _call_target
    return _target_(*args, **kwargs)
  File "/home/yichia3/agrifieldnet/torchgeo/torchgeo/trainers/segmentation.py", line 187, in __init__
    self.config_task()
  File "/home/yichia3/agrifieldnet/torchgeo/torchgeo/trainers/segmentation.py", line 111, in config_task
    state_dict["conv1.weight"] = state_dict["conv1.weight"][:,:12,:,:]
KeyError: 'conv1.weight'

The above exception was the direct cause of the following exception:

Traceback (most recent call last):
  File "/home/yichia3/agrifieldnet/torchgeo/train.py", line 193, in <module>
    main(conf)
  File "/home/yichia3/agrifieldnet/torchgeo/train.py", line 120, in main
    task: LightningModule = instantiate(conf.module)
  File "/projects/dali/spack/var/spack/environments/dali/.spack-env/view/lib/python3.10/site-packages/hydra/_internal/instantiate/_instantiate2.py", line 226, in instantiate
    return instantiate_node(
  File "/projects/dali/spack/var/spack/environments/dali/.spack-env/view/lib/python3.10/site-packages/hydra/_internal/instantiate/_instantiate2.py", line 347, in instantiate_node
    return _call_target(_target_, partial, args, kwargs, full_key)
  File "/projects/dali/spack/var/spack/environments/dali/.spack-env/view/lib/python3.10/site-packages/hydra/_internal/instantiate/_instantiate2.py", line 97, in _call_target
    raise InstantiationException(msg) from e
hydra.errors.InstantiationException: Error in call to target 'torchgeo.trainers.segmentation.SemanticSegmentationTask':
KeyError('conv1.weight')
full_key: module
[rank: 0] Global seed set to 1
Traceback (most recent call last):
  File "/projects/dali/spack/var/spack/environments/dali/.spack-env/view/lib/python3.10/site-packages/hydra/_internal/instantiate/_instantiate2.py", line 92, in _call_target
    return _target_(*args, **kwargs)
  File "/home/yichia3/agrifieldnet/torchgeo/torchgeo/trainers/segmentation.py", line 187, in __init__
    self.config_task()
  File "/home/yichia3/agrifieldnet/torchgeo/torchgeo/trainers/segmentation.py", line 111, in config_task
    state_dict["conv1.weight"] = state_dict["conv1.weight"][:,:12,:,:]
KeyError: 'conv1.weight'

The above exception was the direct cause of the following exception:

Traceback (most recent call last):
  File "/home/yichia3/agrifieldnet/torchgeo/train.py", line 193, in <module>
    main(conf)
  File "/home/yichia3/agrifieldnet/torchgeo/train.py", line 120, in main
    task: LightningModule = instantiate(conf.module)
  File "/projects/dali/spack/var/spack/environments/dali/.spack-env/view/lib/python3.10/site-packages/hydra/_internal/instantiate/_instantiate2.py", line 226, in instantiate
    return instantiate_node(
  File "/projects/dali/spack/var/spack/environments/dali/.spack-env/view/lib/python3.10/site-packages/hydra/_internal/instantiate/_instantiate2.py", line 347, in instantiate_node
    return _call_target(_target_, partial, args, kwargs, full_key)
  File "/projects/dali/spack/var/spack/environments/dali/.spack-env/view/lib/python3.10/site-packages/hydra/_internal/instantiate/_instantiate2.py", line 97, in _call_target
    raise InstantiationException(msg) from e
hydra.errors.InstantiationException: Error in call to target 'torchgeo.trainers.segmentation.SemanticSegmentationTask':
KeyError('conv1.weight')
full_key: module
[rank: 0] Global seed set to 2
Traceback (most recent call last):
  File "/projects/dali/spack/var/spack/environments/dali/.spack-env/view/lib/python3.10/site-packages/hydra/_internal/instantiate/_instantiate2.py", line 92, in _call_target
    return _target_(*args, **kwargs)
  File "/home/yichia3/agrifieldnet/torchgeo/torchgeo/trainers/segmentation.py", line 187, in __init__
    self.config_task()
  File "/home/yichia3/agrifieldnet/torchgeo/torchgeo/trainers/segmentation.py", line 111, in config_task
    state_dict["conv1.weight"] = state_dict["conv1.weight"][:,:12,:,:]
KeyError: 'conv1.weight'

The above exception was the direct cause of the following exception:

Traceback (most recent call last):
  File "/home/yichia3/agrifieldnet/torchgeo/train.py", line 193, in <module>
    main(conf)
  File "/home/yichia3/agrifieldnet/torchgeo/train.py", line 120, in main
    task: LightningModule = instantiate(conf.module)
  File "/projects/dali/spack/var/spack/environments/dali/.spack-env/view/lib/python3.10/site-packages/hydra/_internal/instantiate/_instantiate2.py", line 226, in instantiate
    return instantiate_node(
  File "/projects/dali/spack/var/spack/environments/dali/.spack-env/view/lib/python3.10/site-packages/hydra/_internal/instantiate/_instantiate2.py", line 347, in instantiate_node
    return _call_target(_target_, partial, args, kwargs, full_key)
  File "/projects/dali/spack/var/spack/environments/dali/.spack-env/view/lib/python3.10/site-packages/hydra/_internal/instantiate/_instantiate2.py", line 97, in _call_target
    raise InstantiationException(msg) from e
hydra.errors.InstantiationException: Error in call to target 'torchgeo.trainers.segmentation.SemanticSegmentationTask':
KeyError('conv1.weight')
full_key: module
[rank: 0] Global seed set to 0
Traceback (most recent call last):
  File "/projects/dali/spack/var/spack/environments/dali/.spack-env/view/lib/python3.10/site-packages/hydra/_internal/instantiate/_instantiate2.py", line 92, in _call_target
    return _target_(*args, **kwargs)
  File "/home/yichia3/agrifieldnet/torchgeo/torchgeo/trainers/segmentation.py", line 187, in __init__
    self.config_task()
  File "/home/yichia3/agrifieldnet/torchgeo/torchgeo/trainers/segmentation.py", line 111, in config_task
    state_dict["conv1.weight"] = state_dict["conv1.weight"][:,:12,:,:]
KeyError: 'conv1.weight'

The above exception was the direct cause of the following exception:

Traceback (most recent call last):
  File "/home/yichia3/agrifieldnet/torchgeo/train.py", line 193, in <module>
    main(conf)
  File "/home/yichia3/agrifieldnet/torchgeo/train.py", line 120, in main
    task: LightningModule = instantiate(conf.module)
  File "/projects/dali/spack/var/spack/environments/dali/.spack-env/view/lib/python3.10/site-packages/hydra/_internal/instantiate/_instantiate2.py", line 226, in instantiate
    return instantiate_node(
  File "/projects/dali/spack/var/spack/environments/dali/.spack-env/view/lib/python3.10/site-packages/hydra/_internal/instantiate/_instantiate2.py", line 347, in instantiate_node
    return _call_target(_target_, partial, args, kwargs, full_key)
  File "/projects/dali/spack/var/spack/environments/dali/.spack-env/view/lib/python3.10/site-packages/hydra/_internal/instantiate/_instantiate2.py", line 97, in _call_target
    raise InstantiationException(msg) from e
hydra.errors.InstantiationException: Error in call to target 'torchgeo.trainers.segmentation.SemanticSegmentationTask':
KeyError('conv1.weight')
full_key: module
[rank: 0] Global seed set to 1
Traceback (most recent call last):
  File "/projects/dali/spack/var/spack/environments/dali/.spack-env/view/lib/python3.10/site-packages/hydra/_internal/instantiate/_instantiate2.py", line 92, in _call_target
    return _target_(*args, **kwargs)
  File "/home/yichia3/agrifieldnet/torchgeo/torchgeo/trainers/segmentation.py", line 187, in __init__
    self.config_task()
  File "/home/yichia3/agrifieldnet/torchgeo/torchgeo/trainers/segmentation.py", line 111, in config_task
    state_dict["conv1.weight"] = state_dict["conv1.weight"][:,:12,:,:]
KeyError: 'conv1.weight'

The above exception was the direct cause of the following exception:

Traceback (most recent call last):
  File "/home/yichia3/agrifieldnet/torchgeo/train.py", line 193, in <module>
    main(conf)
  File "/home/yichia3/agrifieldnet/torchgeo/train.py", line 120, in main
    task: LightningModule = instantiate(conf.module)
  File "/projects/dali/spack/var/spack/environments/dali/.spack-env/view/lib/python3.10/site-packages/hydra/_internal/instantiate/_instantiate2.py", line 226, in instantiate
    return instantiate_node(
  File "/projects/dali/spack/var/spack/environments/dali/.spack-env/view/lib/python3.10/site-packages/hydra/_internal/instantiate/_instantiate2.py", line 347, in instantiate_node
    return _call_target(_target_, partial, args, kwargs, full_key)
  File "/projects/dali/spack/var/spack/environments/dali/.spack-env/view/lib/python3.10/site-packages/hydra/_internal/instantiate/_instantiate2.py", line 97, in _call_target
    raise InstantiationException(msg) from e
hydra.errors.InstantiationException: Error in call to target 'torchgeo.trainers.segmentation.SemanticSegmentationTask':
KeyError('conv1.weight')
full_key: module
[rank: 0] Global seed set to 2
Traceback (most recent call last):
  File "/projects/dali/spack/var/spack/environments/dali/.spack-env/view/lib/python3.10/site-packages/hydra/_internal/instantiate/_instantiate2.py", line 92, in _call_target
    return _target_(*args, **kwargs)
  File "/home/yichia3/agrifieldnet/torchgeo/torchgeo/trainers/segmentation.py", line 187, in __init__
    self.config_task()
  File "/home/yichia3/agrifieldnet/torchgeo/torchgeo/trainers/segmentation.py", line 111, in config_task
    state_dict["conv1.weight"] = state_dict["conv1.weight"][:,:12,:,:]
KeyError: 'conv1.weight'

The above exception was the direct cause of the following exception:

Traceback (most recent call last):
  File "/home/yichia3/agrifieldnet/torchgeo/train.py", line 193, in <module>
    main(conf)
  File "/home/yichia3/agrifieldnet/torchgeo/train.py", line 120, in main
    task: LightningModule = instantiate(conf.module)
  File "/projects/dali/spack/var/spack/environments/dali/.spack-env/view/lib/python3.10/site-packages/hydra/_internal/instantiate/_instantiate2.py", line 226, in instantiate
    return instantiate_node(
  File "/projects/dali/spack/var/spack/environments/dali/.spack-env/view/lib/python3.10/site-packages/hydra/_internal/instantiate/_instantiate2.py", line 347, in instantiate_node
    return _call_target(_target_, partial, args, kwargs, full_key)
  File "/projects/dali/spack/var/spack/environments/dali/.spack-env/view/lib/python3.10/site-packages/hydra/_internal/instantiate/_instantiate2.py", line 97, in _call_target
    raise InstantiationException(msg) from e
hydra.errors.InstantiationException: Error in call to target 'torchgeo.trainers.segmentation.SemanticSegmentationTask':
KeyError('conv1.weight')
full_key: module
[rank: 0] Global seed set to 0
Traceback (most recent call last):
  File "/projects/dali/spack/var/spack/environments/dali/.spack-env/view/lib/python3.10/site-packages/hydra/_internal/instantiate/_instantiate2.py", line 92, in _call_target
    return _target_(*args, **kwargs)
  File "/home/yichia3/agrifieldnet/torchgeo/torchgeo/trainers/segmentation.py", line 187, in __init__
    self.config_task()
  File "/home/yichia3/agrifieldnet/torchgeo/torchgeo/trainers/segmentation.py", line 111, in config_task
    state_dict["conv1.weight"] = state_dict["conv1.weight"][:,:12,:,:]
KeyError: 'conv1.weight'

The above exception was the direct cause of the following exception:

Traceback (most recent call last):
  File "/home/yichia3/agrifieldnet/torchgeo/train.py", line 193, in <module>
    main(conf)
  File "/home/yichia3/agrifieldnet/torchgeo/train.py", line 120, in main
    task: LightningModule = instantiate(conf.module)
  File "/projects/dali/spack/var/spack/environments/dali/.spack-env/view/lib/python3.10/site-packages/hydra/_internal/instantiate/_instantiate2.py", line 226, in instantiate
    return instantiate_node(
  File "/projects/dali/spack/var/spack/environments/dali/.spack-env/view/lib/python3.10/site-packages/hydra/_internal/instantiate/_instantiate2.py", line 347, in instantiate_node
    return _call_target(_target_, partial, args, kwargs, full_key)
  File "/projects/dali/spack/var/spack/environments/dali/.spack-env/view/lib/python3.10/site-packages/hydra/_internal/instantiate/_instantiate2.py", line 97, in _call_target
    raise InstantiationException(msg) from e
hydra.errors.InstantiationException: Error in call to target 'torchgeo.trainers.segmentation.SemanticSegmentationTask':
KeyError('conv1.weight')
full_key: module
[rank: 0] Global seed set to 1
Traceback (most recent call last):
  File "/projects/dali/spack/var/spack/environments/dali/.spack-env/view/lib/python3.10/site-packages/hydra/_internal/instantiate/_instantiate2.py", line 92, in _call_target
    return _target_(*args, **kwargs)
  File "/home/yichia3/agrifieldnet/torchgeo/torchgeo/trainers/segmentation.py", line 187, in __init__
    self.config_task()
  File "/home/yichia3/agrifieldnet/torchgeo/torchgeo/trainers/segmentation.py", line 111, in config_task
    state_dict["conv1.weight"] = state_dict["conv1.weight"][:,:12,:,:]
KeyError: 'conv1.weight'

The above exception was the direct cause of the following exception:

Traceback (most recent call last):
  File "/home/yichia3/agrifieldnet/torchgeo/train.py", line 193, in <module>
    main(conf)
  File "/home/yichia3/agrifieldnet/torchgeo/train.py", line 120, in main
    task: LightningModule = instantiate(conf.module)
  File "/projects/dali/spack/var/spack/environments/dali/.spack-env/view/lib/python3.10/site-packages/hydra/_internal/instantiate/_instantiate2.py", line 226, in instantiate
    return instantiate_node(
  File "/projects/dali/spack/var/spack/environments/dali/.spack-env/view/lib/python3.10/site-packages/hydra/_internal/instantiate/_instantiate2.py", line 347, in instantiate_node
    return _call_target(_target_, partial, args, kwargs, full_key)
  File "/projects/dali/spack/var/spack/environments/dali/.spack-env/view/lib/python3.10/site-packages/hydra/_internal/instantiate/_instantiate2.py", line 97, in _call_target
    raise InstantiationException(msg) from e
hydra.errors.InstantiationException: Error in call to target 'torchgeo.trainers.segmentation.SemanticSegmentationTask':
KeyError('conv1.weight')
full_key: module
[rank: 0] Global seed set to 2
Traceback (most recent call last):
  File "/projects/dali/spack/var/spack/environments/dali/.spack-env/view/lib/python3.10/site-packages/hydra/_internal/instantiate/_instantiate2.py", line 92, in _call_target
    return _target_(*args, **kwargs)
  File "/home/yichia3/agrifieldnet/torchgeo/torchgeo/trainers/segmentation.py", line 187, in __init__
    self.config_task()
  File "/home/yichia3/agrifieldnet/torchgeo/torchgeo/trainers/segmentation.py", line 111, in config_task
    state_dict["conv1.weight"] = state_dict["conv1.weight"][:,:12,:,:]
KeyError: 'conv1.weight'

The above exception was the direct cause of the following exception:

Traceback (most recent call last):
  File "/home/yichia3/agrifieldnet/torchgeo/train.py", line 193, in <module>
    main(conf)
  File "/home/yichia3/agrifieldnet/torchgeo/train.py", line 120, in main
    task: LightningModule = instantiate(conf.module)
  File "/projects/dali/spack/var/spack/environments/dali/.spack-env/view/lib/python3.10/site-packages/hydra/_internal/instantiate/_instantiate2.py", line 226, in instantiate
    return instantiate_node(
  File "/projects/dali/spack/var/spack/environments/dali/.spack-env/view/lib/python3.10/site-packages/hydra/_internal/instantiate/_instantiate2.py", line 347, in instantiate_node
    return _call_target(_target_, partial, args, kwargs, full_key)
  File "/projects/dali/spack/var/spack/environments/dali/.spack-env/view/lib/python3.10/site-packages/hydra/_internal/instantiate/_instantiate2.py", line 97, in _call_target
    raise InstantiationException(msg) from e
hydra.errors.InstantiationException: Error in call to target 'torchgeo.trainers.segmentation.SemanticSegmentationTask':
KeyError('conv1.weight')
full_key: module
[rank: 0] Global seed set to 0
Traceback (most recent call last):
  File "/projects/dali/spack/var/spack/environments/dali/.spack-env/view/lib/python3.10/site-packages/hydra/_internal/instantiate/_instantiate2.py", line 92, in _call_target
    return _target_(*args, **kwargs)
  File "/home/yichia3/agrifieldnet/torchgeo/torchgeo/trainers/segmentation.py", line 187, in __init__
    self.config_task()
  File "/home/yichia3/agrifieldnet/torchgeo/torchgeo/trainers/segmentation.py", line 111, in config_task
    state_dict["conv1.weight"] = state_dict["conv1.weight"][:,:12,:,:]
KeyError: 'conv1.weight'

The above exception was the direct cause of the following exception:

Traceback (most recent call last):
  File "/home/yichia3/agrifieldnet/torchgeo/train.py", line 193, in <module>
    main(conf)
  File "/home/yichia3/agrifieldnet/torchgeo/train.py", line 120, in main
    task: LightningModule = instantiate(conf.module)
  File "/projects/dali/spack/var/spack/environments/dali/.spack-env/view/lib/python3.10/site-packages/hydra/_internal/instantiate/_instantiate2.py", line 226, in instantiate
    return instantiate_node(
  File "/projects/dali/spack/var/spack/environments/dali/.spack-env/view/lib/python3.10/site-packages/hydra/_internal/instantiate/_instantiate2.py", line 347, in instantiate_node
    return _call_target(_target_, partial, args, kwargs, full_key)
  File "/projects/dali/spack/var/spack/environments/dali/.spack-env/view/lib/python3.10/site-packages/hydra/_internal/instantiate/_instantiate2.py", line 97, in _call_target
    raise InstantiationException(msg) from e
hydra.errors.InstantiationException: Error in call to target 'torchgeo.trainers.segmentation.SemanticSegmentationTask':
KeyError('conv1.weight')
full_key: module
[rank: 0] Global seed set to 1
Traceback (most recent call last):
  File "/projects/dali/spack/var/spack/environments/dali/.spack-env/view/lib/python3.10/site-packages/hydra/_internal/instantiate/_instantiate2.py", line 92, in _call_target
    return _target_(*args, **kwargs)
  File "/home/yichia3/agrifieldnet/torchgeo/torchgeo/trainers/segmentation.py", line 187, in __init__
    self.config_task()
  File "/home/yichia3/agrifieldnet/torchgeo/torchgeo/trainers/segmentation.py", line 111, in config_task
    state_dict["conv1.weight"] = state_dict["conv1.weight"][:,:12,:,:]
KeyError: 'conv1.weight'

The above exception was the direct cause of the following exception:

Traceback (most recent call last):
  File "/home/yichia3/agrifieldnet/torchgeo/train.py", line 193, in <module>
    main(conf)
  File "/home/yichia3/agrifieldnet/torchgeo/train.py", line 120, in main
    task: LightningModule = instantiate(conf.module)
  File "/projects/dali/spack/var/spack/environments/dali/.spack-env/view/lib/python3.10/site-packages/hydra/_internal/instantiate/_instantiate2.py", line 226, in instantiate
    return instantiate_node(
  File "/projects/dali/spack/var/spack/environments/dali/.spack-env/view/lib/python3.10/site-packages/hydra/_internal/instantiate/_instantiate2.py", line 347, in instantiate_node
    return _call_target(_target_, partial, args, kwargs, full_key)
  File "/projects/dali/spack/var/spack/environments/dali/.spack-env/view/lib/python3.10/site-packages/hydra/_internal/instantiate/_instantiate2.py", line 97, in _call_target
    raise InstantiationException(msg) from e
hydra.errors.InstantiationException: Error in call to target 'torchgeo.trainers.segmentation.SemanticSegmentationTask':
KeyError('conv1.weight')
full_key: module
[rank: 0] Global seed set to 2
Traceback (most recent call last):
  File "/projects/dali/spack/var/spack/environments/dali/.spack-env/view/lib/python3.10/site-packages/hydra/_internal/instantiate/_instantiate2.py", line 92, in _call_target
    return _target_(*args, **kwargs)
  File "/home/yichia3/agrifieldnet/torchgeo/torchgeo/trainers/segmentation.py", line 187, in __init__
    self.config_task()
  File "/home/yichia3/agrifieldnet/torchgeo/torchgeo/trainers/segmentation.py", line 111, in config_task
    state_dict["conv1.weight"] = state_dict["conv1.weight"][:,:12,:,:]
KeyError: 'conv1.weight'

The above exception was the direct cause of the following exception:

Traceback (most recent call last):
  File "/home/yichia3/agrifieldnet/torchgeo/train.py", line 193, in <module>
    main(conf)
  File "/home/yichia3/agrifieldnet/torchgeo/train.py", line 120, in main
    task: LightningModule = instantiate(conf.module)
  File "/projects/dali/spack/var/spack/environments/dali/.spack-env/view/lib/python3.10/site-packages/hydra/_internal/instantiate/_instantiate2.py", line 226, in instantiate
    return instantiate_node(
  File "/projects/dali/spack/var/spack/environments/dali/.spack-env/view/lib/python3.10/site-packages/hydra/_internal/instantiate/_instantiate2.py", line 347, in instantiate_node
    return _call_target(_target_, partial, args, kwargs, full_key)
  File "/projects/dali/spack/var/spack/environments/dali/.spack-env/view/lib/python3.10/site-packages/hydra/_internal/instantiate/_instantiate2.py", line 97, in _call_target
    raise InstantiationException(msg) from e
hydra.errors.InstantiationException: Error in call to target 'torchgeo.trainers.segmentation.SemanticSegmentationTask':
KeyError('conv1.weight')
full_key: module
[rank: 0] Global seed set to 0
Traceback (most recent call last):
  File "/projects/dali/spack/var/spack/environments/dali/.spack-env/view/lib/python3.10/site-packages/hydra/_internal/instantiate/_instantiate2.py", line 92, in _call_target
    return _target_(*args, **kwargs)
  File "/home/yichia3/agrifieldnet/torchgeo/torchgeo/trainers/segmentation.py", line 187, in __init__
    self.config_task()
  File "/home/yichia3/agrifieldnet/torchgeo/torchgeo/trainers/segmentation.py", line 111, in config_task
    state_dict["conv1.weight"] = state_dict["conv1.weight"][:,:12,:,:]
KeyError: 'conv1.weight'

The above exception was the direct cause of the following exception:

Traceback (most recent call last):
  File "/home/yichia3/agrifieldnet/torchgeo/train.py", line 193, in <module>
    main(conf)
  File "/home/yichia3/agrifieldnet/torchgeo/train.py", line 120, in main
    task: LightningModule = instantiate(conf.module)
  File "/projects/dali/spack/var/spack/environments/dali/.spack-env/view/lib/python3.10/site-packages/hydra/_internal/instantiate/_instantiate2.py", line 226, in instantiate
    return instantiate_node(
  File "/projects/dali/spack/var/spack/environments/dali/.spack-env/view/lib/python3.10/site-packages/hydra/_internal/instantiate/_instantiate2.py", line 347, in instantiate_node
    return _call_target(_target_, partial, args, kwargs, full_key)
  File "/projects/dali/spack/var/spack/environments/dali/.spack-env/view/lib/python3.10/site-packages/hydra/_internal/instantiate/_instantiate2.py", line 97, in _call_target
    raise InstantiationException(msg) from e
hydra.errors.InstantiationException: Error in call to target 'torchgeo.trainers.segmentation.SemanticSegmentationTask':
KeyError('conv1.weight')
full_key: module
[rank: 0] Global seed set to 1
Traceback (most recent call last):
  File "/projects/dali/spack/var/spack/environments/dali/.spack-env/view/lib/python3.10/site-packages/hydra/_internal/instantiate/_instantiate2.py", line 92, in _call_target
    return _target_(*args, **kwargs)
  File "/home/yichia3/agrifieldnet/torchgeo/torchgeo/trainers/segmentation.py", line 187, in __init__
    self.config_task()
  File "/home/yichia3/agrifieldnet/torchgeo/torchgeo/trainers/segmentation.py", line 111, in config_task
    state_dict["conv1.weight"] = state_dict["conv1.weight"][:,:12,:,:]
KeyError: 'conv1.weight'

The above exception was the direct cause of the following exception:

Traceback (most recent call last):
  File "/home/yichia3/agrifieldnet/torchgeo/train.py", line 193, in <module>
    main(conf)
  File "/home/yichia3/agrifieldnet/torchgeo/train.py", line 120, in main
    task: LightningModule = instantiate(conf.module)
  File "/projects/dali/spack/var/spack/environments/dali/.spack-env/view/lib/python3.10/site-packages/hydra/_internal/instantiate/_instantiate2.py", line 226, in instantiate
    return instantiate_node(
  File "/projects/dali/spack/var/spack/environments/dali/.spack-env/view/lib/python3.10/site-packages/hydra/_internal/instantiate/_instantiate2.py", line 347, in instantiate_node
    return _call_target(_target_, partial, args, kwargs, full_key)
  File "/projects/dali/spack/var/spack/environments/dali/.spack-env/view/lib/python3.10/site-packages/hydra/_internal/instantiate/_instantiate2.py", line 97, in _call_target
    raise InstantiationException(msg) from e
hydra.errors.InstantiationException: Error in call to target 'torchgeo.trainers.segmentation.SemanticSegmentationTask':
KeyError('conv1.weight')
full_key: module
[rank: 0] Global seed set to 2
Traceback (most recent call last):
  File "/projects/dali/spack/var/spack/environments/dali/.spack-env/view/lib/python3.10/site-packages/hydra/_internal/instantiate/_instantiate2.py", line 92, in _call_target
    return _target_(*args, **kwargs)
  File "/home/yichia3/agrifieldnet/torchgeo/torchgeo/trainers/segmentation.py", line 187, in __init__
    self.config_task()
  File "/home/yichia3/agrifieldnet/torchgeo/torchgeo/trainers/segmentation.py", line 111, in config_task
    state_dict["conv1.weight"] = state_dict["conv1.weight"][:,:12,:,:]
KeyError: 'conv1.weight'

The above exception was the direct cause of the following exception:

Traceback (most recent call last):
  File "/home/yichia3/agrifieldnet/torchgeo/train.py", line 193, in <module>
    main(conf)
  File "/home/yichia3/agrifieldnet/torchgeo/train.py", line 120, in main
    task: LightningModule = instantiate(conf.module)
  File "/projects/dali/spack/var/spack/environments/dali/.spack-env/view/lib/python3.10/site-packages/hydra/_internal/instantiate/_instantiate2.py", line 226, in instantiate
    return instantiate_node(
  File "/projects/dali/spack/var/spack/environments/dali/.spack-env/view/lib/python3.10/site-packages/hydra/_internal/instantiate/_instantiate2.py", line 347, in instantiate_node
    return _call_target(_target_, partial, args, kwargs, full_key)
  File "/projects/dali/spack/var/spack/environments/dali/.spack-env/view/lib/python3.10/site-packages/hydra/_internal/instantiate/_instantiate2.py", line 97, in _call_target
    raise InstantiationException(msg) from e
hydra.errors.InstantiationException: Error in call to target 'torchgeo.trainers.segmentation.SemanticSegmentationTask':
KeyError('conv1.weight')
full_key: module
[rank: 0] Global seed set to 0
Traceback (most recent call last):
  File "/projects/dali/spack/var/spack/environments/dali/.spack-env/view/lib/python3.10/site-packages/hydra/_internal/instantiate/_instantiate2.py", line 92, in _call_target
    return _target_(*args, **kwargs)
  File "/home/yichia3/agrifieldnet/torchgeo/torchgeo/trainers/segmentation.py", line 187, in __init__
    self.config_task()
  File "/home/yichia3/agrifieldnet/torchgeo/torchgeo/trainers/segmentation.py", line 111, in config_task
    state_dict["conv1.weight"] = state_dict["conv1.weight"][:,:12,:,:]
KeyError: 'conv1.weight'

The above exception was the direct cause of the following exception:

Traceback (most recent call last):
  File "/home/yichia3/agrifieldnet/torchgeo/train.py", line 193, in <module>
    main(conf)
  File "/home/yichia3/agrifieldnet/torchgeo/train.py", line 120, in main
    task: LightningModule = instantiate(conf.module)
  File "/projects/dali/spack/var/spack/environments/dali/.spack-env/view/lib/python3.10/site-packages/hydra/_internal/instantiate/_instantiate2.py", line 226, in instantiate
    return instantiate_node(
  File "/projects/dali/spack/var/spack/environments/dali/.spack-env/view/lib/python3.10/site-packages/hydra/_internal/instantiate/_instantiate2.py", line 347, in instantiate_node
    return _call_target(_target_, partial, args, kwargs, full_key)
  File "/projects/dali/spack/var/spack/environments/dali/.spack-env/view/lib/python3.10/site-packages/hydra/_internal/instantiate/_instantiate2.py", line 97, in _call_target
    raise InstantiationException(msg) from e
hydra.errors.InstantiationException: Error in call to target 'torchgeo.trainers.segmentation.SemanticSegmentationTask':
KeyError('conv1.weight')
full_key: module
[rank: 0] Global seed set to 1
Traceback (most recent call last):
  File "/projects/dali/spack/var/spack/environments/dali/.spack-env/view/lib/python3.10/site-packages/hydra/_internal/instantiate/_instantiate2.py", line 92, in _call_target
    return _target_(*args, **kwargs)
  File "/home/yichia3/agrifieldnet/torchgeo/torchgeo/trainers/segmentation.py", line 187, in __init__
    self.config_task()
  File "/home/yichia3/agrifieldnet/torchgeo/torchgeo/trainers/segmentation.py", line 111, in config_task
    state_dict["conv1.weight"] = state_dict["conv1.weight"][:,:12,:,:]
KeyError: 'conv1.weight'

The above exception was the direct cause of the following exception:

Traceback (most recent call last):
  File "/home/yichia3/agrifieldnet/torchgeo/train.py", line 193, in <module>
    main(conf)
  File "/home/yichia3/agrifieldnet/torchgeo/train.py", line 120, in main
    task: LightningModule = instantiate(conf.module)
  File "/projects/dali/spack/var/spack/environments/dali/.spack-env/view/lib/python3.10/site-packages/hydra/_internal/instantiate/_instantiate2.py", line 226, in instantiate
    return instantiate_node(
  File "/projects/dali/spack/var/spack/environments/dali/.spack-env/view/lib/python3.10/site-packages/hydra/_internal/instantiate/_instantiate2.py", line 347, in instantiate_node
    return _call_target(_target_, partial, args, kwargs, full_key)
  File "/projects/dali/spack/var/spack/environments/dali/.spack-env/view/lib/python3.10/site-packages/hydra/_internal/instantiate/_instantiate2.py", line 97, in _call_target
    raise InstantiationException(msg) from e
hydra.errors.InstantiationException: Error in call to target 'torchgeo.trainers.segmentation.SemanticSegmentationTask':
KeyError('conv1.weight')
full_key: module
[rank: 0] Global seed set to 2
Traceback (most recent call last):
  File "/projects/dali/spack/var/spack/environments/dali/.spack-env/view/lib/python3.10/site-packages/hydra/_internal/instantiate/_instantiate2.py", line 92, in _call_target
    return _target_(*args, **kwargs)
  File "/home/yichia3/agrifieldnet/torchgeo/torchgeo/trainers/segmentation.py", line 187, in __init__
    self.config_task()
  File "/home/yichia3/agrifieldnet/torchgeo/torchgeo/trainers/segmentation.py", line 111, in config_task
    state_dict["conv1.weight"] = state_dict["conv1.weight"][:,:12,:,:]
KeyError: 'conv1.weight'

The above exception was the direct cause of the following exception:

Traceback (most recent call last):
  File "/home/yichia3/agrifieldnet/torchgeo/train.py", line 193, in <module>
    main(conf)
  File "/home/yichia3/agrifieldnet/torchgeo/train.py", line 120, in main
    task: LightningModule = instantiate(conf.module)
  File "/projects/dali/spack/var/spack/environments/dali/.spack-env/view/lib/python3.10/site-packages/hydra/_internal/instantiate/_instantiate2.py", line 226, in instantiate
    return instantiate_node(
  File "/projects/dali/spack/var/spack/environments/dali/.spack-env/view/lib/python3.10/site-packages/hydra/_internal/instantiate/_instantiate2.py", line 347, in instantiate_node
    return _call_target(_target_, partial, args, kwargs, full_key)
  File "/projects/dali/spack/var/spack/environments/dali/.spack-env/view/lib/python3.10/site-packages/hydra/_internal/instantiate/_instantiate2.py", line 97, in _call_target
    raise InstantiationException(msg) from e
hydra.errors.InstantiationException: Error in call to target 'torchgeo.trainers.segmentation.SemanticSegmentationTask':
KeyError('conv1.weight')
full_key: module
python train.py config_file=conf/agrifieldnet.yaml module.model=unet module.backbone=tu-vit_small_patch16_224 module.learning_rate=0.01 module.loss=ce module.weights=ViTSmall16_Weights.SENTINEL2_ALL_MOCO datamodule.patch_size=224 program.experiment_name=agrifieldnet_unet_tu-vit_small_patch16_224_0.01_ce_ViTSmall16_Weights.SENTINEL2_ALL_MOCO_0.001_0 program.seed=0 trainer.devices=[0]
python train.py config_file=conf/agrifieldnet.yaml module.model=unet module.backbone=tu-vit_small_patch16_224 module.learning_rate=0.01 module.loss=ce module.weights=ViTSmall16_Weights.SENTINEL2_ALL_MOCO datamodule.patch_size=224 program.experiment_name=agrifieldnet_unet_tu-vit_small_patch16_224_0.01_ce_ViTSmall16_Weights.SENTINEL2_ALL_MOCO_0.001_1 program.seed=1 trainer.devices=[0]
python train.py config_file=conf/agrifieldnet.yaml module.model=unet module.backbone=tu-vit_small_patch16_224 module.learning_rate=0.01 module.loss=ce module.weights=ViTSmall16_Weights.SENTINEL2_ALL_MOCO datamodule.patch_size=224 program.experiment_name=agrifieldnet_unet_tu-vit_small_patch16_224_0.01_ce_ViTSmall16_Weights.SENTINEL2_ALL_MOCO_0.001_2 program.seed=2 trainer.devices=[0]
python train.py config_file=conf/agrifieldnet.yaml module.model=unet module.backbone=tu-vit_small_patch16_224 module.learning_rate=0.01 module.loss=ce module.weights=ViTSmall16_Weights.SENTINEL2_ALL_DINO datamodule.patch_size=224 program.experiment_name=agrifieldnet_unet_tu-vit_small_patch16_224_0.01_ce_ViTSmall16_Weights.SENTINEL2_ALL_DINO_0.001_0 program.seed=0 trainer.devices=[0]
python train.py config_file=conf/agrifieldnet.yaml module.model=unet module.backbone=tu-vit_small_patch16_224 module.learning_rate=0.01 module.loss=ce module.weights=ViTSmall16_Weights.SENTINEL2_ALL_DINO datamodule.patch_size=224 program.experiment_name=agrifieldnet_unet_tu-vit_small_patch16_224_0.01_ce_ViTSmall16_Weights.SENTINEL2_ALL_DINO_0.001_1 program.seed=1 trainer.devices=[0]
python train.py config_file=conf/agrifieldnet.yaml module.model=unet module.backbone=tu-vit_small_patch16_224 module.learning_rate=0.01 module.loss=ce module.weights=ViTSmall16_Weights.SENTINEL2_ALL_DINO datamodule.patch_size=224 program.experiment_name=agrifieldnet_unet_tu-vit_small_patch16_224_0.01_ce_ViTSmall16_Weights.SENTINEL2_ALL_DINO_0.001_2 program.seed=2 trainer.devices=[0]
python train.py config_file=conf/agrifieldnet.yaml module.model=unet module.backbone=tu-vit_small_patch16_224 module.learning_rate=0.05 module.loss=ce module.weights=ViTSmall16_Weights.SENTINEL2_ALL_MOCO datamodule.patch_size=224 program.experiment_name=agrifieldnet_unet_tu-vit_small_patch16_224_0.05_ce_ViTSmall16_Weights.SENTINEL2_ALL_MOCO_0.001_0 program.seed=0 trainer.devices=[0]
python train.py config_file=conf/agrifieldnet.yaml module.model=unet module.backbone=tu-vit_small_patch16_224 module.learning_rate=0.05 module.loss=ce module.weights=ViTSmall16_Weights.SENTINEL2_ALL_MOCO datamodule.patch_size=224 program.experiment_name=agrifieldnet_unet_tu-vit_small_patch16_224_0.05_ce_ViTSmall16_Weights.SENTINEL2_ALL_MOCO_0.001_1 program.seed=1 trainer.devices=[0]
python train.py config_file=conf/agrifieldnet.yaml module.model=unet module.backbone=tu-vit_small_patch16_224 module.learning_rate=0.05 module.loss=ce module.weights=ViTSmall16_Weights.SENTINEL2_ALL_MOCO datamodule.patch_size=224 program.experiment_name=agrifieldnet_unet_tu-vit_small_patch16_224_0.05_ce_ViTSmall16_Weights.SENTINEL2_ALL_MOCO_0.001_2 program.seed=2 trainer.devices=[0]
python train.py config_file=conf/agrifieldnet.yaml module.model=unet module.backbone=tu-vit_small_patch16_224 module.learning_rate=0.05 module.loss=ce module.weights=ViTSmall16_Weights.SENTINEL2_ALL_DINO datamodule.patch_size=224 program.experiment_name=agrifieldnet_unet_tu-vit_small_patch16_224_0.05_ce_ViTSmall16_Weights.SENTINEL2_ALL_DINO_0.001_0 program.seed=0 trainer.devices=[0]
python train.py config_file=conf/agrifieldnet.yaml module.model=unet module.backbone=tu-vit_small_patch16_224 module.learning_rate=0.05 module.loss=ce module.weights=ViTSmall16_Weights.SENTINEL2_ALL_DINO datamodule.patch_size=224 program.experiment_name=agrifieldnet_unet_tu-vit_small_patch16_224_0.05_ce_ViTSmall16_Weights.SENTINEL2_ALL_DINO_0.001_1 program.seed=1 trainer.devices=[0]
python train.py config_file=conf/agrifieldnet.yaml module.model=unet module.backbone=tu-vit_small_patch16_224 module.learning_rate=0.05 module.loss=ce module.weights=ViTSmall16_Weights.SENTINEL2_ALL_DINO datamodule.patch_size=224 program.experiment_name=agrifieldnet_unet_tu-vit_small_patch16_224_0.05_ce_ViTSmall16_Weights.SENTINEL2_ALL_DINO_0.001_2 program.seed=2 trainer.devices=[0]
python train.py config_file=conf/agrifieldnet.yaml module.model=unet module.backbone=tu-vit_small_patch16_224 module.learning_rate=0.001 module.loss=ce module.weights=ViTSmall16_Weights.SENTINEL2_ALL_MOCO datamodule.patch_size=224 program.experiment_name=agrifieldnet_unet_tu-vit_small_patch16_224_0.001_ce_ViTSmall16_Weights.SENTINEL2_ALL_MOCO_0.001_0 program.seed=0 trainer.devices=[0]
python train.py config_file=conf/agrifieldnet.yaml module.model=unet module.backbone=tu-vit_small_patch16_224 module.learning_rate=0.001 module.loss=ce module.weights=ViTSmall16_Weights.SENTINEL2_ALL_MOCO datamodule.patch_size=224 program.experiment_name=agrifieldnet_unet_tu-vit_small_patch16_224_0.001_ce_ViTSmall16_Weights.SENTINEL2_ALL_MOCO_0.001_1 program.seed=1 trainer.devices=[0]
python train.py config_file=conf/agrifieldnet.yaml module.model=unet module.backbone=tu-vit_small_patch16_224 module.learning_rate=0.001 module.loss=ce module.weights=ViTSmall16_Weights.SENTINEL2_ALL_MOCO datamodule.patch_size=224 program.experiment_name=agrifieldnet_unet_tu-vit_small_patch16_224_0.001_ce_ViTSmall16_Weights.SENTINEL2_ALL_MOCO_0.001_2 program.seed=2 trainer.devices=[0]
python train.py config_file=conf/agrifieldnet.yaml module.model=unet module.backbone=tu-vit_small_patch16_224 module.learning_rate=0.001 module.loss=ce module.weights=ViTSmall16_Weights.SENTINEL2_ALL_DINO datamodule.patch_size=224 program.experiment_name=agrifieldnet_unet_tu-vit_small_patch16_224_0.001_ce_ViTSmall16_Weights.SENTINEL2_ALL_DINO_0.001_0 program.seed=0 trainer.devices=[0]
python train.py config_file=conf/agrifieldnet.yaml module.model=unet module.backbone=tu-vit_small_patch16_224 module.learning_rate=0.001 module.loss=ce module.weights=ViTSmall16_Weights.SENTINEL2_ALL_DINO datamodule.patch_size=224 program.experiment_name=agrifieldnet_unet_tu-vit_small_patch16_224_0.001_ce_ViTSmall16_Weights.SENTINEL2_ALL_DINO_0.001_1 program.seed=1 trainer.devices=[0]
python train.py config_file=conf/agrifieldnet.yaml module.model=unet module.backbone=tu-vit_small_patch16_224 module.learning_rate=0.001 module.loss=ce module.weights=ViTSmall16_Weights.SENTINEL2_ALL_DINO datamodule.patch_size=224 program.experiment_name=agrifieldnet_unet_tu-vit_small_patch16_224_0.001_ce_ViTSmall16_Weights.SENTINEL2_ALL_DINO_0.001_2 program.seed=2 trainer.devices=[0]
python train.py config_file=conf/agrifieldnet.yaml module.model=unet module.backbone=tu-vit_small_patch16_224 module.learning_rate=0.005 module.loss=ce module.weights=ViTSmall16_Weights.SENTINEL2_ALL_MOCO datamodule.patch_size=224 program.experiment_name=agrifieldnet_unet_tu-vit_small_patch16_224_0.005_ce_ViTSmall16_Weights.SENTINEL2_ALL_MOCO_0.001_0 program.seed=0 trainer.devices=[0]
python train.py config_file=conf/agrifieldnet.yaml module.model=unet module.backbone=tu-vit_small_patch16_224 module.learning_rate=0.005 module.loss=ce module.weights=ViTSmall16_Weights.SENTINEL2_ALL_MOCO datamodule.patch_size=224 program.experiment_name=agrifieldnet_unet_tu-vit_small_patch16_224_0.005_ce_ViTSmall16_Weights.SENTINEL2_ALL_MOCO_0.001_1 program.seed=1 trainer.devices=[0]
python train.py config_file=conf/agrifieldnet.yaml module.model=unet module.backbone=tu-vit_small_patch16_224 module.learning_rate=0.005 module.loss=ce module.weights=ViTSmall16_Weights.SENTINEL2_ALL_MOCO datamodule.patch_size=224 program.experiment_name=agrifieldnet_unet_tu-vit_small_patch16_224_0.005_ce_ViTSmall16_Weights.SENTINEL2_ALL_MOCO_0.001_2 program.seed=2 trainer.devices=[0]
python train.py config_file=conf/agrifieldnet.yaml module.model=unet module.backbone=tu-vit_small_patch16_224 module.learning_rate=0.005 module.loss=ce module.weights=ViTSmall16_Weights.SENTINEL2_ALL_DINO datamodule.patch_size=224 program.experiment_name=agrifieldnet_unet_tu-vit_small_patch16_224_0.005_ce_ViTSmall16_Weights.SENTINEL2_ALL_DINO_0.001_0 program.seed=0 trainer.devices=[0]
python train.py config_file=conf/agrifieldnet.yaml module.model=unet module.backbone=tu-vit_small_patch16_224 module.learning_rate=0.005 module.loss=ce module.weights=ViTSmall16_Weights.SENTINEL2_ALL_DINO datamodule.patch_size=224 program.experiment_name=agrifieldnet_unet_tu-vit_small_patch16_224_0.005_ce_ViTSmall16_Weights.SENTINEL2_ALL_DINO_0.001_1 program.seed=1 trainer.devices=[0]
python train.py config_file=conf/agrifieldnet.yaml module.model=unet module.backbone=tu-vit_small_patch16_224 module.learning_rate=0.005 module.loss=ce module.weights=ViTSmall16_Weights.SENTINEL2_ALL_DINO datamodule.patch_size=224 program.experiment_name=agrifieldnet_unet_tu-vit_small_patch16_224_0.005_ce_ViTSmall16_Weights.SENTINEL2_ALL_DINO_0.001_2 program.seed=2 trainer.devices=[0]
python train.py config_file=conf/agrifieldnet.yaml module.model=unet module.backbone=tu-vit_small_patch16_224 module.learning_rate=0.0001 module.loss=ce module.weights=ViTSmall16_Weights.SENTINEL2_ALL_MOCO datamodule.patch_size=224 program.experiment_name=agrifieldnet_unet_tu-vit_small_patch16_224_0.0001_ce_ViTSmall16_Weights.SENTINEL2_ALL_MOCO_0.001_0 program.seed=0 trainer.devices=[0]
python train.py config_file=conf/agrifieldnet.yaml module.model=unet module.backbone=tu-vit_small_patch16_224 module.learning_rate=0.0001 module.loss=ce module.weights=ViTSmall16_Weights.SENTINEL2_ALL_MOCO datamodule.patch_size=224 program.experiment_name=agrifieldnet_unet_tu-vit_small_patch16_224_0.0001_ce_ViTSmall16_Weights.SENTINEL2_ALL_MOCO_0.001_1 program.seed=1 trainer.devices=[0]
python train.py config_file=conf/agrifieldnet.yaml module.model=unet module.backbone=tu-vit_small_patch16_224 module.learning_rate=0.0001 module.loss=ce module.weights=ViTSmall16_Weights.SENTINEL2_ALL_MOCO datamodule.patch_size=224 program.experiment_name=agrifieldnet_unet_tu-vit_small_patch16_224_0.0001_ce_ViTSmall16_Weights.SENTINEL2_ALL_MOCO_0.001_2 program.seed=2 trainer.devices=[0]
python train.py config_file=conf/agrifieldnet.yaml module.model=unet module.backbone=tu-vit_small_patch16_224 module.learning_rate=0.0001 module.loss=ce module.weights=ViTSmall16_Weights.SENTINEL2_ALL_DINO datamodule.patch_size=224 program.experiment_name=agrifieldnet_unet_tu-vit_small_patch16_224_0.0001_ce_ViTSmall16_Weights.SENTINEL2_ALL_DINO_0.001_0 program.seed=0 trainer.devices=[0]
python train.py config_file=conf/agrifieldnet.yaml module.model=unet module.backbone=tu-vit_small_patch16_224 module.learning_rate=0.0001 module.loss=ce module.weights=ViTSmall16_Weights.SENTINEL2_ALL_DINO datamodule.patch_size=224 program.experiment_name=agrifieldnet_unet_tu-vit_small_patch16_224_0.0001_ce_ViTSmall16_Weights.SENTINEL2_ALL_DINO_0.001_1 program.seed=1 trainer.devices=[0]
python train.py config_file=conf/agrifieldnet.yaml module.model=unet module.backbone=tu-vit_small_patch16_224 module.learning_rate=0.0001 module.loss=ce module.weights=ViTSmall16_Weights.SENTINEL2_ALL_DINO datamodule.patch_size=224 program.experiment_name=agrifieldnet_unet_tu-vit_small_patch16_224_0.0001_ce_ViTSmall16_Weights.SENTINEL2_ALL_DINO_0.001_2 program.seed=2 trainer.devices=[0]
